Traceback (most recent call last):
  File "/Users/kaituranski/Documents/School/McGill/U4/Fall 2024/COMP 551/Assignments/Assignment 4/COMP-551-A4/local.env/lib/python3.10/site-packages/transformers/utils/hub.py", line 403, in cached_file
    resolved_file = hf_hub_download(
  File "/Users/kaituranski/Documents/School/McGill/U4/Fall 2024/COMP 551/Assignments/Assignment 4/COMP-551-A4/local.env/lib/python3.10/site-packages/huggingface_hub/utils/_validators.py", line 106, in _inner_fn
    validate_repo_id(arg_value)
  File "/Users/kaituranski/Documents/School/McGill/U4/Fall 2024/COMP 551/Assignments/Assignment 4/COMP-551-A4/local.env/lib/python3.10/site-packages/huggingface_hub/utils/_validators.py", line 154, in validate_repo_id
    raise HFValidationError(
huggingface_hub.errors.HFValidationError: Repo id must be in the form 'repo_name' or 'namespace/repo_name': '/opt/models/bert-base-uncased'. Use `repo_type` argument if needed.

The above exception was the direct cause of the following exception:

Traceback (most recent call last):
  File "/Users/kaituranski/Documents/School/McGill/U4/Fall 2024/COMP 551/Assignments/Assignment 4/COMP-551-A4/jobs/local/../../python/BERT_experiments/over_epochs.py", line 131, in <module>
    tokenizer = AutoTokenizer.from_pretrained(model_path)
  File "/Users/kaituranski/Documents/School/McGill/U4/Fall 2024/COMP 551/Assignments/Assignment 4/COMP-551-A4/local.env/lib/python3.10/site-packages/transformers/models/auto/tokenization_auto.py", line 858, in from_pretrained
    tokenizer_config = get_tokenizer_config(pretrained_model_name_or_path, **kwargs)
  File "/Users/kaituranski/Documents/School/McGill/U4/Fall 2024/COMP 551/Assignments/Assignment 4/COMP-551-A4/local.env/lib/python3.10/site-packages/transformers/models/auto/tokenization_auto.py", line 690, in get_tokenizer_config
    resolved_config_file = cached_file(
  File "/Users/kaituranski/Documents/School/McGill/U4/Fall 2024/COMP 551/Assignments/Assignment 4/COMP-551-A4/local.env/lib/python3.10/site-packages/transformers/utils/hub.py", line 469, in cached_file
    raise EnvironmentError(
OSError: Incorrect path_or_model_id: '/opt/models/bert-base-uncased'. Please provide either the path to a local folder or the repo_id of a model on the Hub.
